[2024-12-04T23:19:43.379+0000] {local_task_job_runner.py:123} INFO - ::group::Pre task execution logs
[2024-12-04T23:19:43.404+0000] {taskinstance.py:2613} INFO - Dependencies all met for dep_context=non-requeueable deps ti=<TaskInstance: etl_pipeline.load_to_postgres manual__2024-12-04T23:19:37.688659+00:00 [queued]>
[2024-12-04T23:19:43.417+0000] {taskinstance.py:2613} INFO - Dependencies all met for dep_context=requeueable deps ti=<TaskInstance: etl_pipeline.load_to_postgres manual__2024-12-04T23:19:37.688659+00:00 [queued]>
[2024-12-04T23:19:43.418+0000] {taskinstance.py:2866} INFO - Starting attempt 1 of 1
[2024-12-04T23:19:43.436+0000] {taskinstance.py:2889} INFO - Executing <Task(PythonOperator): load_to_postgres> on 2024-12-04 23:19:37.688659+00:00
[2024-12-04T23:19:43.445+0000] {warnings.py:112} WARNING - /home/***/.local/lib/python3.12/site-packages/***/task/task_runner/standard_task_runner.py:70: DeprecationWarning: This process (pid=792) is multi-threaded, use of fork() may lead to deadlocks in the child.
  pid = os.fork()

[2024-12-04T23:19:43.447+0000] {standard_task_runner.py:72} INFO - Started process 794 to run task
[2024-12-04T23:19:43.447+0000] {standard_task_runner.py:104} INFO - Running: ['***', 'tasks', 'run', 'etl_pipeline', 'load_to_postgres', 'manual__2024-12-04T23:19:37.688659+00:00', '--job-id', '98', '--raw', '--subdir', 'DAGS_FOLDER/etl_pipeline.py', '--cfg-path', '/tmp/tmp73hob81z']
[2024-12-04T23:19:43.449+0000] {standard_task_runner.py:105} INFO - Job 98: Subtask load_to_postgres
[2024-12-04T23:19:43.517+0000] {task_command.py:467} INFO - Running <TaskInstance: etl_pipeline.load_to_postgres manual__2024-12-04T23:19:37.688659+00:00 [running]> on host f697cea74b34
[2024-12-04T23:19:43.831+0000] {taskinstance.py:3132} INFO - Exporting env vars: AIRFLOW_CTX_DAG_OWNER='***' AIRFLOW_CTX_DAG_ID='etl_pipeline' AIRFLOW_CTX_TASK_ID='load_to_postgres' AIRFLOW_CTX_EXECUTION_DATE='2024-12-04T23:19:37.688659+00:00' AIRFLOW_CTX_TRY_NUMBER='1' AIRFLOW_CTX_DAG_RUN_ID='manual__2024-12-04T23:19:37.688659+00:00'
[2024-12-04T23:19:43.833+0000] {logging_mixin.py:190} INFO - Task instance is in running state
[2024-12-04T23:19:43.833+0000] {logging_mixin.py:190} INFO -  Previous state of the Task instance: queued
[2024-12-04T23:19:43.834+0000] {logging_mixin.py:190} INFO - Current task name:load_to_postgres state:running start_date:2024-12-04 23:19:43.405725+00:00
[2024-12-04T23:19:43.835+0000] {logging_mixin.py:190} INFO - Dag name:etl_pipeline and current dag run status:running
[2024-12-04T23:19:43.836+0000] {taskinstance.py:731} INFO - ::endgroup::
[2024-12-04T23:19:43.862+0000] {base.py:84} INFO - Retrieving connection 'postgres_conn'
[2024-12-04T23:19:43.874+0000] {taskinstance.py:3311} ERROR - Task failed with exception
Traceback (most recent call last):
  File "/home/airflow/.local/lib/python3.12/site-packages/airflow/models/taskinstance.py", line 767, in _execute_task
    result = _execute_callable(context=context, **execute_callable_kwargs)
             ^^^^^^^^^^^^^^^^^^^^^^^^^^^^^^^^^^^^^^^^^^^^^^^^^^^^^^^^^^^^^
  File "/home/airflow/.local/lib/python3.12/site-packages/airflow/models/taskinstance.py", line 733, in _execute_callable
    return ExecutionCallableRunner(
           ^^^^^^^^^^^^^^^^^^^^^^^^
  File "/home/airflow/.local/lib/python3.12/site-packages/airflow/utils/operator_helpers.py", line 252, in run
    return self.func(*args, **kwargs)
           ^^^^^^^^^^^^^^^^^^^^^^^^^^
  File "/home/airflow/.local/lib/python3.12/site-packages/airflow/models/baseoperator.py", line 417, in wrapper
    return func(self, *args, **kwargs)
           ^^^^^^^^^^^^^^^^^^^^^^^^^^^
  File "/home/airflow/.local/lib/python3.12/site-packages/airflow/operators/python.py", line 238, in execute
    return_value = self.execute_callable()
                   ^^^^^^^^^^^^^^^^^^^^^^^
  File "/home/airflow/.local/lib/python3.12/site-packages/airflow/operators/python.py", line 256, in execute_callable
    return runner.run(*self.op_args, **self.op_kwargs)
           ^^^^^^^^^^^^^^^^^^^^^^^^^^^^^^^^^^^^^^^^^^^
  File "/home/airflow/.local/lib/python3.12/site-packages/airflow/utils/operator_helpers.py", line 252, in run
    return self.func(*args, **kwargs)
           ^^^^^^^^^^^^^^^^^^^^^^^^^^
  File "/opt/airflow/dags/etl_pipeline.py", line 26, in load_to_postgres
    conn = pg_hook.get_conn()
           ^^^^^^^^^^^^^^^^^^
  File "/home/airflow/.local/lib/python3.12/site-packages/airflow/providers/postgres/hooks/postgres.py", line 181, in get_conn
    self.conn = psycopg2.connect(**conn_args)
                ^^^^^^^^^^^^^^^^^^^^^^^^^^^^^
  File "/home/airflow/.local/lib/python3.12/site-packages/psycopg2/__init__.py", line 122, in connect
    conn = _connect(dsn, connection_factory=connection_factory, **kwasync)
           ^^^^^^^^^^^^^^^^^^^^^^^^^^^^^^^^^^^^^^^^^^^^^^^^^^^^^^^^^^^^^^^
psycopg2.OperationalError: connection to server at "host.docker.internal" (192.168.65.254), port 5450 failed: server closed the connection unexpectedly
	This probably means the server terminated abnormally
	before or while processing the request.

[2024-12-04T23:19:43.888+0000] {logging_mixin.py:190} INFO - Task instance in failure state
[2024-12-04T23:19:43.889+0000] {logging_mixin.py:190} INFO - Task start:2024-12-04 23:19:43.405725+00:00 end:2024-12-04 23:19:43.888498+00:00 duration:0.482773
[2024-12-04T23:19:43.890+0000] {logging_mixin.py:190} INFO - Task:<Task(PythonOperator): load_to_postgres> dag:<DAG: etl_pipeline> dagrun:<DagRun etl_pipeline @ 2024-12-04 23:19:37.688659+00:00: manual__2024-12-04T23:19:37.688659+00:00, state:running, queued_at: 2024-12-04 23:19:37.717796+00:00. externally triggered: True>
[2024-12-04T23:19:43.891+0000] {logging_mixin.py:190} INFO - Failure caused by connection to server at "host.docker.internal" (192.168.65.254), port 5450 failed: server closed the connection unexpectedly
	This probably means the server terminated abnormally
	before or while processing the request.
[2024-12-04T23:19:43.891+0000] {taskinstance.py:1225} INFO - Marking task as FAILED. dag_id=etl_pipeline, task_id=load_to_postgres, run_id=manual__2024-12-04T23:19:37.688659+00:00, execution_date=20241204T231937, start_date=20241204T231943, end_date=20241204T231943
[2024-12-04T23:19:43.907+0000] {taskinstance.py:340} INFO - ::group::Post task execution logs
[2024-12-04T23:19:43.909+0000] {standard_task_runner.py:124} ERROR - Failed to execute job 98 for task load_to_postgres (connection to server at "host.docker.internal" (192.168.65.254), port 5450 failed: server closed the connection unexpectedly
	This probably means the server terminated abnormally
	before or while processing the request.
; 794)
Traceback (most recent call last):
  File "/home/airflow/.local/lib/python3.12/site-packages/airflow/task/task_runner/standard_task_runner.py", line 117, in _start_by_fork
    ret = args.func(args, dag=self.dag)
          ^^^^^^^^^^^^^^^^^^^^^^^^^^^^^
  File "/home/airflow/.local/lib/python3.12/site-packages/airflow/cli/cli_config.py", line 49, in command
    return func(*args, **kwargs)
           ^^^^^^^^^^^^^^^^^^^^^
  File "/home/airflow/.local/lib/python3.12/site-packages/airflow/utils/cli.py", line 116, in wrapper
    return f(*args, **kwargs)
           ^^^^^^^^^^^^^^^^^^
  File "/home/airflow/.local/lib/python3.12/site-packages/airflow/cli/commands/task_command.py", line 483, in task_run
    task_return_code = _run_task_by_selected_method(args, _dag, ti)
                       ^^^^^^^^^^^^^^^^^^^^^^^^^^^^^^^^^^^^^^^^^^^^
  File "/home/airflow/.local/lib/python3.12/site-packages/airflow/cli/commands/task_command.py", line 256, in _run_task_by_selected_method
    return _run_raw_task(args, ti)
           ^^^^^^^^^^^^^^^^^^^^^^^
  File "/home/airflow/.local/lib/python3.12/site-packages/airflow/cli/commands/task_command.py", line 341, in _run_raw_task
    return ti._run_raw_task(
           ^^^^^^^^^^^^^^^^^
  File "/home/airflow/.local/lib/python3.12/site-packages/airflow/utils/session.py", line 97, in wrapper
    return func(*args, session=session, **kwargs)
           ^^^^^^^^^^^^^^^^^^^^^^^^^^^^^^^^^^^^^^
  File "/home/airflow/.local/lib/python3.12/site-packages/airflow/models/taskinstance.py", line 3005, in _run_raw_task
    return _run_raw_task(
           ^^^^^^^^^^^^^^
  File "/home/airflow/.local/lib/python3.12/site-packages/airflow/models/taskinstance.py", line 273, in _run_raw_task
    TaskInstance._execute_task_with_callbacks(
  File "/home/airflow/.local/lib/python3.12/site-packages/airflow/models/taskinstance.py", line 3159, in _execute_task_with_callbacks
    result = self._execute_task(context, task_orig)
             ^^^^^^^^^^^^^^^^^^^^^^^^^^^^^^^^^^^^^^
  File "/home/airflow/.local/lib/python3.12/site-packages/airflow/models/taskinstance.py", line 3183, in _execute_task
    return _execute_task(self, context, task_orig)
           ^^^^^^^^^^^^^^^^^^^^^^^^^^^^^^^^^^^^^^^
  File "/home/airflow/.local/lib/python3.12/site-packages/airflow/models/taskinstance.py", line 767, in _execute_task
    result = _execute_callable(context=context, **execute_callable_kwargs)
             ^^^^^^^^^^^^^^^^^^^^^^^^^^^^^^^^^^^^^^^^^^^^^^^^^^^^^^^^^^^^^
  File "/home/airflow/.local/lib/python3.12/site-packages/airflow/models/taskinstance.py", line 733, in _execute_callable
    return ExecutionCallableRunner(
           ^^^^^^^^^^^^^^^^^^^^^^^^
  File "/home/airflow/.local/lib/python3.12/site-packages/airflow/utils/operator_helpers.py", line 252, in run
    return self.func(*args, **kwargs)
           ^^^^^^^^^^^^^^^^^^^^^^^^^^
  File "/home/airflow/.local/lib/python3.12/site-packages/airflow/models/baseoperator.py", line 417, in wrapper
    return func(self, *args, **kwargs)
           ^^^^^^^^^^^^^^^^^^^^^^^^^^^
  File "/home/airflow/.local/lib/python3.12/site-packages/airflow/operators/python.py", line 238, in execute
    return_value = self.execute_callable()
                   ^^^^^^^^^^^^^^^^^^^^^^^
  File "/home/airflow/.local/lib/python3.12/site-packages/airflow/operators/python.py", line 256, in execute_callable
    return runner.run(*self.op_args, **self.op_kwargs)
           ^^^^^^^^^^^^^^^^^^^^^^^^^^^^^^^^^^^^^^^^^^^
  File "/home/airflow/.local/lib/python3.12/site-packages/airflow/utils/operator_helpers.py", line 252, in run
    return self.func(*args, **kwargs)
           ^^^^^^^^^^^^^^^^^^^^^^^^^^
  File "/opt/airflow/dags/etl_pipeline.py", line 26, in load_to_postgres
    conn = pg_hook.get_conn()
           ^^^^^^^^^^^^^^^^^^
  File "/home/airflow/.local/lib/python3.12/site-packages/airflow/providers/postgres/hooks/postgres.py", line 181, in get_conn
    self.conn = psycopg2.connect(**conn_args)
                ^^^^^^^^^^^^^^^^^^^^^^^^^^^^^
  File "/home/airflow/.local/lib/python3.12/site-packages/psycopg2/__init__.py", line 122, in connect
    conn = _connect(dsn, connection_factory=connection_factory, **kwasync)
           ^^^^^^^^^^^^^^^^^^^^^^^^^^^^^^^^^^^^^^^^^^^^^^^^^^^^^^^^^^^^^^^
psycopg2.OperationalError: connection to server at "host.docker.internal" (192.168.65.254), port 5450 failed: server closed the connection unexpectedly
	This probably means the server terminated abnormally
	before or while processing the request.

[2024-12-04T23:19:43.947+0000] {local_task_job_runner.py:266} INFO - Task exited with return code 1
[2024-12-04T23:19:43.976+0000] {taskinstance.py:3895} INFO - 0 downstream tasks scheduled from follow-on schedule check
[2024-12-04T23:19:43.983+0000] {local_task_job_runner.py:245} INFO - ::endgroup::
